Workbook

Sheet EMP_1
B1: TOTAL ATIVO | C1: =SUM(C11+C29+C42) -> 0 | E1: =SUM(E11+E29+E42) -> 0 | G1: =SUM(G11+G29+G42) -> 0 | I1: =SUM(I11+I29+I42) -> 0
B2: TOTAL PASSIVO | C2: =C51+C79+C97+C99+C101 -> 0 | E2: =E51+E79+E97+E99+E101 -> 0 | G2: =G51+G79+G97+G99+G101 -> 0 | I2: =I51+I79+I97+I99+I101 -> 0
B3: DIFERENÇA | C3: =C1-C2 -> 0 | E3: =E1-E2 -> 0 | G3: =G1-G2 -> 0 | I3: =I1-I2 -> 0
B5: EMPRESA 1 LTDA
B7: BALANÇO PATRIMONIAL
C8: 44896 | E8: 45261 | G8: 45627 | I8: 45992
B9: ATIVO | C9: R$ MIL | D9: (%) | E9: R$ MIL | F9: (%) | G9: R$ MIL | H9: (%) | I9: R$ MIL | J9: (%)
B11: CIRCULANTE | C11: =SUM(C12:C27) -> 0 | D11: =IF($C$47="ERRO","ERRO",IF($C$47=0,0,C11/$C$47)) -> 0 | E11: =SUM(E12:E27) -> 0 | F11: =IF($E$47="ERRO","ERRO",IF($E$47=0,0,E11/$E$47)) -> 0 | G11: =SUM(G12:G27) -> 0 | H11: =IF($G$47="ERRO","ERRO",IF($G$47=0,0,G11/$G$47)) -> 0 | I11: =SUM(I12:I27) -> 0 | J11: =IF($I$47="ERRO","ERRO",IF($I$47=0,0,I11/$I$47)) -> 0
B12: Caixa e Bancos | D12: =IF($C$47="ERRO","ERRO",IF($C$47=0,0,C12/$C$47)) -> 0 | F12: =IF($E$47="ERRO","ERRO",IF($E$47=0,0,E12/$E$47)) -> 0 | H12: =IF($G$47="ERRO","ERRO",IF($G$47=0,0,G12/$G$47)) -> 0 | J12: =IF($I$47="ERRO","ERRO",IF($I$47=0,0,I12/$I$47)) -> 0
B13: Aplicações Financeiras | D13: =IF($C$47="ERRO","ERRO",IF($C$47=0,0,C13/$C$47)) -> 0 | F13: =IF($E$47="ERRO","ERRO",IF($E$47=0,0,E13/$E$47)) -> 0 | H13: =IF($G$47="ERRO","ERRO",IF($G$47=0,0,G13/$G$47)) -> 0 | J13: =IF($I$47="ERRO","ERRO",IF($I$47=0,0,I13/$I$47)) -> 0
B14: Contas a Receber | D14: =IF($C$47="ERRO","ERRO",IF($C$47=0,0,C14/$C$47)) -> 0 | F14: =IF($E$47="ERRO","ERRO",IF($E$47=0,0,E14/$E$47)) -> 0 | H14: =IF($G$47="ERRO","ERRO",IF($G$47=0,0,G14/$G$47)) -> 0 | J14: =IF($I$47="ERRO","ERRO",IF($I$47=0,0,I14/$I$47)) -> 0
B15: Cooperados | D15: =IF($C$47="ERRO","ERRO",IF($C$47=0,0,C15/$C$47)) -> 0 | F15: =IF($E$47="ERRO","ERRO",IF($E$47=0,0,E15/$E$47)) -> 0 | H15: =IF($G$47="ERRO","ERRO",IF($G$47=0,0,G15/$G$47)) -> 0 | J15: =IF($I$47="ERRO","ERRO",IF($I$47=0,0,I15/$I$47)) -> 0
B16: CVA | D16: =IF($C$47="ERRO","ERRO",IF($C$47=0,0,C16/$C$47)) -> 0 | F16: =IF($E$47="ERRO","ERRO",IF($E$47=0,0,E16/$E$47)) -> 0 | H16: =IF($G$47="ERRO","ERRO",IF($G$47=0,0,G16/$G$47)) -> 0 | J16: =IF($I$47="ERRO","ERRO",IF($I$47=0,0,I16/$I$47)) -> 0
B17: Estoques | D17: =IF($C$47="ERRO","ERRO",IF($C$47=0,0,C17/$C$47)) -> 0 | F17: =IF($E$47="ERRO","ERRO",IF($E$47=0,0,E17/$E$47)) -> 0 | H17: =IF($G$47="ERRO","ERRO",IF($G$47=0,0,G17/$G$47)) -> 0 | J17: =IF($I$47="ERRO","ERRO",IF($I$47=0,0,I17/$I$47)) -> 0
B18: Adiant. a Fornecedores | D18: =IF($C$47="ERRO","ERRO",IF($C$47=0,0,C18/$C$47)) -> 0 | F18: =IF($E$47="ERRO","ERRO",IF($E$47=0,0,E18/$E$47)) -> 0 | H18: =IF($G$47="ERRO","ERRO",IF($G$47=0,0,G18/$G$47)) -> 0 | J18: =IF($I$47="ERRO","ERRO",IF($I$47=0,0,I18/$I$47)) -> 0
B19: Créditos a Fumicultores | D19: =IF($C$47="ERRO","ERRO",IF($C$47=0,0,C19/$C$47)) -> 0 | F19: =IF($E$47="ERRO","ERRO",IF($E$47=0,0,E19/$E$47)) -> 0 | H19: =IF($G$47="ERRO","ERRO",IF($G$47=0,0,G19/$G$47)) -> 0 | J19: =IF($I$47="ERRO","ERRO",IF($I$47=0,0,I19/$I$47)) -> 0
B20: Despesas Antecipadas | D20: =IF($C$47="ERRO","ERRO",IF($C$47=0,0,C20/$C$47)) -> 0 | F20: =IF($E$47="ERRO","ERRO",IF($E$47=0,0,E20/$E$47)) -> 0 | H20: =IF($G$47="ERRO","ERRO",IF($G$47=0,0,G20/$G$47)) -> 0 | J20: =IF($I$47="ERRO","ERRO",IF($I$47=0,0,I20/$I$47)) -> 0
B21: Impostos a Recuperar | D21: =IF($C$47="ERRO","ERRO",IF($C$47=0,0,C21/$C$47)) -> 0 | F21: =IF($E$47="ERRO","ERRO",IF($E$47=0,0,E21/$E$47)) -> 0 | H21: =IF($G$47="ERRO","ERRO",IF($G$47=0,0,G21/$G$47)) -> 0 | J21: =IF($I$47="ERRO","ERRO",IF($I$47=0,0,I21/$I$47)) -> 0
B22: Dividendos a Receber | D22: =IF($C$47="ERRO","ERRO",IF($C$47=0,0,C22/$C$47)) -> 0 | F22: =IF($E$47="ERRO","ERRO",IF($E$47=0,0,E22/$E$47)) -> 0 | H22: =IF($G$47="ERRO","ERRO",IF($G$47=0,0,G22/$G$47)) -> 0 | J22: =IF($I$47="ERRO","ERRO",IF($I$47=0,0,I22/$I$47)) -> 0
B23: Imposto Diferido | D23: =IF($C$47="ERRO","ERRO",IF($C$47=0,0,C23/$C$47)) -> 0 | F23: =IF($E$47="ERRO","ERRO",IF($E$47=0,0,E23/$E$47)) -> 0 | H23: =IF($G$47="ERRO","ERRO",IF($G$47=0,0,G23/$G$47)) -> 0 | J23: =IF($I$47="ERRO","ERRO",IF($I$47=0,0,I23/$I$47)) -> 0
... B27: Outros Nao Operac. | D27: =IF($C$47="ERRO","ERRO",IF($C$47=0,0,C27/$C$47)) -> 0 | F27: =IF($E$47="ERRO","ERRO",IF($E$47=0,0,E27/$E$47)) -> 0 | H27: =IF($G$47="ERRO","ERRO",IF($G$47=0,0,G27/$G$47)) -> 0 | J27: =IF($I$47="ERRO","ERRO",IF($I$47=0,0,I27/$I$47)) -> 0
B29: REALIZ. L.P. | C29: =SUM(C30:C40) -> 0 | D29: =IF($C$47="ERRO","ERRO",IF($C$47=0,0,C29/$C$47)) -> 0 | E29: =SUM(E30:E40) -> 0 | F29: =IF($E$47="ERRO","ERRO",IF($E$47=0,0,E29/$E$47)) -> 0 | G29: =SUM(G30:G40) -> 0 | H29: =IF($G$47="ERRO","ERRO",IF($G$47=0,0,G29/$G$47)) -> 0 | I29: =SUM(I30:I40) -> 0 | J29: =IF($I$47="ERRO","ERRO",IF($I$47=0,0,I29/$I$47)) -> 0
B30: Contas a Receber | D30: =IF($C$47="ERRO","ERRO",IF($C$47=0,0,C30/$C$47)) -> 0 | F30: =IF($E$47="ERRO","ERRO",IF($E$47=0,0,E30/$E$47)) -> 0 | H30: =IF($G$47="ERRO","ERRO",IF($G$47=0,0,G30/$G$47)) -> 0 | J30: =IF($I$47="ERRO","ERRO",IF($I$47=0,0,I30/$I$47)) -> 0
B31: Cooperados | D31: =IF($C$47="ERRO","ERRO",IF($C$47=0,0,C31/$C$47)) -> 0 | F31: =IF($E$47="ERRO","ERRO",IF($E$47=0,0,E31/$E$47)) -> 0 | H31: =IF($G$47="ERRO","ERRO",IF($G$47=0,0,G31/$G$47)) -> 0 | J31: =IF($I$47="ERRO","ERRO",IF($I$47=0,0,I31/$I$47)) -> 0
B32: C/C Coligadas/Acionistas | D32: =IF($C$47="ERRO","ERRO",IF($C$47=0,0,C32/$C$47)) -> 0 | F32: =IF($E$47="ERRO","ERRO",IF($E$47=0,0,E32/$E$47)) -> 0 | H32: =IF($G$47="ERRO","ERRO",IF($G$47=0,0,G32/$G$47)) -> 0 | J32: =IF($I$47="ERRO","ERRO",IF($I$47=0,0,I32/$I$47)) -> 0
B33: Depósitos Judiciais | D33: =IF($C$47="ERRO","ERRO",IF($C$47=0,0,C33/$C$47)) -> 0 | F33: =IF($E$47="ERRO","ERRO",IF($E$47=0,0,E33/$E$47)) -> 0 | H33: =IF($G$47="ERRO","ERRO",IF($G$47=0,0,G33/$G$47)) -> 0 | J33: =IF($I$47="ERRO","ERRO",IF($I$47=0,0,I33/$I$47)) -> 0
B34: Imposto Diferido | D34: =IF($C$47="ERRO","ERRO",IF($C$47=0,0,C34/$C$47)) -> 0 | F34: =IF($E$47="ERRO","ERRO",IF($E$47=0,0,E34/$E$47)) -> 0 | H34: =IF($G$47="ERRO","ERRO",IF($G$47=0,0,G34/$G$47)) -> 0 | J34: =IF($I$47="ERRO","ERRO",IF($I$47=0,0,I34/$I$47)) -> 0
B35: Créditos a Fumicultores | D35: =IF($C$47="ERRO","ERRO",IF($C$47=0,0,C35/$C$47)) -> 0 | F35: =IF($E$47="ERRO","ERRO",IF($E$47=0,0,E35/$E$47)) -> 0 | H35: =IF($G$47="ERRO","ERRO",IF($G$47=0,0,G35/$G$47)) -> 0 | J35: =IF($I$47="ERRO","ERRO",IF($I$47=0,0,I35/$I$47)) -> 0
B36: CTN´s | D36: =IF($C$47="ERRO","ERRO",IF($C$47=0,0,C36/$C$47)) -> 0 | F36: =IF($E$47="ERRO","ERRO",IF($E$47=0,0,E36/$E$47)) -> 0 | H36: =IF($G$47="ERRO","ERRO",IF($G$47=0,0,G36/$G$47)) -> 0 | J36: =IF($I$47="ERRO","ERRO",IF($I$47=0,0,I36/$I$47)) -> 0
B37: Outros Operac. | D37: =IF($C$47="ERRO","ERRO",IF($C$47=0,0,C37/$C$47)) -> 0 | F37: =IF($E$47="ERRO","ERRO",IF($E$47=0,0,E37/$E$47)) -> 0 | H37: =IF($G$47="ERRO","ERRO",IF($G$47=0,0,G37/$G$47)) -> 0 | J37: =IF($I$47="ERRO","ERRO",IF($I$47=0,0,I37/$I$47)) -> 0
B38: Outros Operac. | D38: =IF($C$47="ERRO","ERRO",IF($C$47=0,0,C38/$C$47)) -> 0 | F38: =IF($E$47="ERRO","ERRO",IF($E$47=0,0,E38/$E$47)) -> 0 | H38: =IF($G$47="ERRO","ERRO",IF($G$47=0,0,G38/$G$47)) -> 0 | J38: =IF($I$47="ERRO","ERRO",IF($I$47=0,0,I38/$I$47)) -> 0
B39: Outros Nao Operac. | D39: =IF($C$47="ERRO","ERRO",IF($C$47=0,0,C39/$C$47)) -> 0 | F39: =IF($E$47="ERRO","ERRO",IF($E$47=0,0,E39/$E$47)) -> 0 | H39: =IF($G$47="ERRO","ERRO",IF($G$47=0,0,G39/$G$47)) -> 0 | J39: =IF($I$47="ERRO","ERRO",IF($I$47=0,0,I39/$I$47)) -> 0
B40: Outros Nao Operac. | D40: =IF($C$47="ERRO","ERRO",IF($C$47=0,0,C40/$C$47)) -> 0 | F40: =IF($E$47="ERRO","ERRO",IF($E$47=0,0,E40/$E$47)) -> 0 | H40: =IF($G$47="ERRO","ERRO",IF($G$47=0,0,G40/$G$47)) -> 0 | J40: =IF($I$47="ERRO","ERRO",IF($I$47=0,0,I40/$I$47)) -> 0
B42: PERMANENTE | C42: =SUM(C43:C45) -> 0 | D42: =IF($C$47="ERRO","ERRO",IF($C$47=0,0,C42/$C$47)) -> 0 | E42: =SUM(E43:E45) -> 0 | F42: =IF($E$47="ERRO","ERRO",IF($E$47=0,0,E42/$E$47)) -> 0 | G42: =SUM(G43:G45) -> 0 | H42: =IF($G$47="ERRO","ERRO",IF($G$47=0,0,G42/$G$47)) -> 0 | I42: =SUM(I43:I45) -> 0 | J42: =IF($I$47="ERRO","ERRO",IF($I$47=0,0,I42/$I$47)) -> 0
B43: Imobilizado Técnico | D43: =IF($C$47="ERRO","ERRO",IF($C$47=0,0,C43/$C$47)) -> 0 | F43: =IF($E$47="ERRO","ERRO",IF($E$47=0,0,E43/$E$47)) -> 0 | H43: =IF($G$47="ERRO","ERRO",IF($G$47=0,0,G43/$G$47)) -> 0 | J43: =IF($I$47="ERRO","ERRO",IF($I$47=0,0,I43/$I$47)) -> 0
B44: Investimentos | D44: =IF($C$47="ERRO","ERRO",IF($C$47=0,0,C44/$C$47)) -> 0 | F44: =IF($E$47="ERRO","ERRO",IF($E$47=0,0,E44/$E$47)) -> 0 | H44: =IF($G$47="ERRO","ERRO",IF($G$47=0,0,G44/$G$47)) -> 0 | J44: =IF($I$47="ERRO","ERRO",IF($I$47=0,0,I44/$I$47)) -> 0
B45: Diferido/Intangível | D45: =IF($C$47="ERRO","ERRO",IF($C$47=0,0,C45/$C$47)) -> 0 | F45: =IF($E$47="ERRO","ERRO",IF($E$47=0,0,E45/$E$47)) -> 0 | H45: =IF($G$47="ERRO","ERRO",IF($G$47=0,0,G45/$G$47)) -> 0 | J45: =IF($I$47="ERRO","ERRO",IF($I$47=0,0,I45/$I$47)) -> 0
B47: TOTAL | C47: =IF(OR(C11+C29+C42-C51-C79-C97-C99-C101>1,C11+C29+C42-C51-C79-C97-C99-C101<-1),"ERRO",C11+C29+C42) -> 0 | D47: =IF($C$47="ERRO","ERRO",IF($C$47=0,0,C47/$C$47)) -> 0 | E47: =IF(OR(E11+E29+E42-E51-E79-E97-E99-E101>1,E11+E29+E42-E51-E79-E97-E99-E101<-1),"ERRO",E11+E29+E42) -> 0 | F47: =IF($E$47="ERRO","ERRO",IF($E$47=0,0,E47/$E$47)) -> 0 | G47: =IF(OR(G11+G29+G42-G51-G79-G97-G99-G101>1,G11+G29+G42-G51-G79-G97-G99-G101<-1),"ERRO",G11+G29+G42) -> 0 | H47: =IF($G$47="ERRO","ERRO",IF($G$47=0,0,G47/$G$47)) -> 0 | I47: =IF(OR(I11+I29+I42-I51-I79-I97-I99-I101>1,I11+I29+I42-I51-I79-I97-I99-I101<-1),"ERRO",I11+I29+I42) -> 0 | J47: =IF($I$47="ERRO","ERRO",IF($I$47=0,0,I47/$I$47)) -> 0
B49: PASSIVO | C49: R$ MIL | D49: (%) | E49: R$ MIL | F49: (%) | G49: R$ MIL | H49: (%) | I49: R$ MIL | J49: (%)
B51: CIRCULANTE | C51: =SUM(C52:C77) -> 0 | D51: =IF($C$47="ERRO","ERRO",IF($C$47=0,0,C51/$C$47)) -> 0 | E51: =SUM(E52:E77) -> 0 | F51: =IF($E$47="ERRO","ERRO",IF($E$47=0,0,E51/$E$47)) -> 0 | G51: =SUM(G52:G77) -> 0 | H51: =IF($G$47="ERRO","ERRO",IF($G$47=0,0,G51/$G$47)) -> 0 | I51: =SUM(I52:I77) -> 0 | J51: =IF($I$47="ERRO","ERRO",IF($I$47=0,0,I51/$I$47)) -> 0
...

Sheet EMP_2
B1: TOTAL ATIVO | C1: =SUM(C11+C29+C42) -> 0 | E1: =SUM(E11+E29+E42) -> 0 | G1: =SUM(G11+G29+G42) -> 0 | I1: =SUM(I11+I29+I42) -> 0
B2: TOTAL PASSIVO | C2: =C51+C79+C97+C99+C101 -> 0 | E2: =E51+E79+E97+E99+E101 -> 0 | G2: =G51+G79+G97+G99+G101 -> 0 | I2: =I51+I79+I97+I99+I101 -> 0
B3: DIFERENÇA | C3: =C1-C2 -> 0 | E3: =E1-E2 -> 0 | G3: =G1-G2 -> 0 | I3: =I1-I2 -> 0
B5: EMPRESA 2 LTDA
B7: BALANÇO PATRIMONIAL
C8: 44896 | E8: 45261 | G8: 45627 | I8: 45992
B9: ATIVO | C9: R$ MIL | D9: (%) | E9: R$ MIL | F9: (%) | G9: R$ MIL | H9: (%) | I9: R$ MIL | J9: (%)
B11: CIRCULANTE | C11: =SUM(C12:C27) -> 0 | D11: =IF($C$48="ERRO","ERRO",IF($C$48=0,0,C11/$C$48)) -> 0 | E11: =SUM(E12:E27) -> 0 | F11: =IF($E$48="ERRO","ERRO",IF($E$48=0,0,E11/$E$48)) -> 0 | G11: =SUM(G12:G27) -> 0 | H11: =IF($G$48="ERRO","ERRO",IF($G$48=0,0,G11/$G$48)) -> 0 | I11: =SUM(I12:I27) -> 0 | J11: =IF($I$48="ERRO","ERRO",IF($I$48=0,0,I11/$I$48)) -> 0
B12: Caixa e Bancos | D12: =IF($C$48="ERRO","ERRO",IF($C$48=0,0,C12/$C$48)) -> 0 | F12: =IF($E$48="ERRO","ERRO",IF($E$48=0,0,E12/$E$48)) -> 0 | H12: =IF($G$48="ERRO","ERRO",IF($G$48=0,0,G12/$G$48)) -> 0 | J12: =IF($I$48="ERRO","ERRO",IF($I$48=0,0,I12/$I$48)) -> 0
B13: Aplicações Financeiras | D13: =IF($C$48="ERRO","ERRO",IF($C$48=0,0,C13/$C$48)) -> 0 | F13: =IF($E$48="ERRO","ERRO",IF($E$48=0,0,E13/$E$48)) -> 0 | H13: =IF($G$48="ERRO","ERRO",IF($G$48=0,0,G13/$G$48)) -> 0 | J13: =IF($I$48="ERRO","ERRO",IF($I$48=0,0,I13/$I$48)) -> 0
B14: Contas a Receber | D14: =IF($C$48="ERRO","ERRO",IF($C$48=0,0,C14/$C$48)) -> 0 | F14: =IF($E$48="ERRO","ERRO",IF($E$48=0,0,E14/$E$48)) -> 0 | H14: =IF($G$48="ERRO","ERRO",IF($G$48=0,0,G14/$G$48)) -> 0 | J14: =IF($I$48="ERRO","ERRO",IF($I$48=0,0,I14/$I$48)) -> 0
B15: Cooperados | D15: =IF($C$48="ERRO","ERRO",IF($C$48=0,0,C15/$C$48)) -> 0 | F15: =IF($E$48="ERRO","ERRO",IF($E$48=0,0,E15/$E$48)) -> 0 | H15: =IF($G$48="ERRO","ERRO",IF($G$48=0,0,G15/$G$48)) -> 0 | J15: =IF($I$48="ERRO","ERRO",IF($I$48=0,0,I15/$I$48)) -> 0
B16: CVA | D16: =IF($C$48="ERRO","ERRO",IF($C$48=0,0,C16/$C$48)) -> 0 | F16: =IF($E$48="ERRO","ERRO",IF($E$48=0,0,E16/$E$48)) -> 0 | H16: =IF($G$48="ERRO","ERRO",IF($G$48=0,0,G16/$G$48)) -> 0 | J16: =IF($I$48="ERRO","ERRO",IF($I$48=0,0,I16/$I$48)) -> 0
B17: Estoques | D17: =IF($C$48="ERRO","ERRO",IF($C$48=0,0,C17/$C$48)) -> 0 | F17: =IF($E$48="ERRO","ERRO",IF($E$48=0,0,E17/$E$48)) -> 0 | H17: =IF($G$48="ERRO","ERRO",IF($G$48=0,0,G17/$G$48)) -> 0 | J17: =IF($I$48="ERRO","ERRO",IF($I$48=0,0,I17/$I$48)) -> 0
B18: Adiant. a Fornecedores | D18: =IF($C$48="ERRO","ERRO",IF($C$48=0,0,C18/$C$48)) -> 0 | F18: =IF($E$48="ERRO","ERRO",IF($E$48=0,0,E18/$E$48)) -> 0 | H18: =IF($G$48="ERRO","ERRO",IF($G$48=0,0,G18/$G$48)) -> 0 | J18: =IF($I$48="ERRO","ERRO",IF($I$48=0,0,I18/$I$48)) -> 0
B19: Créditos a Fumicultores | D19: =IF($C$48="ERRO","ERRO",IF($C$48=0,0,C19/$C$48)) -> 0 | F19: =IF($E$48="ERRO","ERRO",IF($E$48=0,0,E19/$E$48)) -> 0 | H19: =IF($G$48="ERRO","ERRO",IF($G$48=0,0,G19/$G$48)) -> 0 | J19: =IF($I$48="ERRO","ERRO",IF($I$48=0,0,I19/$I$48)) -> 0
B20: Despesas Antecipadas | D20: =IF($C$48="ERRO","ERRO",IF($C$48=0,0,C20/$C$48)) -> 0 | F20: =IF($E$48="ERRO","ERRO",IF($E$48=0,0,E20/$E$48)) -> 0 | H20: =IF($G$48="ERRO","ERRO",IF($G$48=0,0,G20/$G$48)) -> 0 | J20: =IF($I$48="ERRO","ERRO",IF($I$48=0,0,I20/$I$48)) -> 0
B21: Impostos a Recuperar | D21: =IF($C$48="ERRO","ERRO",IF($C$48=0,0,C21/$C$48)) -> 0 | F21: =IF($E$48="ERRO","ERRO",IF($E$48=0,0,E21/$E$48)) -> 0 | H21: =IF($G$48="ERRO","ERRO",IF($G$48=0,0,G21/$G$48)) -> 0 | J21: =IF($I$48="ERRO","ERRO",IF($I$48=0,0,I21/$I$48)) -> 0
B22: Dividendos a Receber | D22: =IF($C$48="ERRO","ERRO",IF($C$48=0,0,C22/$C$48)) -> 0 | F22: =IF($E$48="ERRO","ERRO",IF($E$48=0,0,E22/$E$48)) -> 0 | H22: =IF($G$48="ERRO","ERRO",IF($G$48=0,0,G22/$G$48)) -> 0 | J22: =IF($I$48="ERRO","ERRO",IF($I$48=0,0,I22/$I$48)) -> 0
B23: Imposto Diferido | D23: =IF($C$48="ERRO","ERRO",IF($C$48=0,0,C23/$C$48)) -> 0 | F23: =IF($E$48="ERRO","ERRO",IF($E$48=0,0,E23/$E$48)) -> 0 | H23: =IF($G$48="ERRO","ERRO",IF($G$48=0,0,G23/$G$48)) -> 0 | J23: =IF($I$48="ERRO","ERRO",IF($I$48=0,0,I23/$I$48)) -> 0
... B27: Outros Nao Operac. | D27: =IF($C$48="ERRO","ERRO",IF($C$48=0,0,C27/$C$48)) -> 0 | F27: =IF($E$48="ERRO","ERRO",IF($E$48=0,0,E27/$E$48)) -> 0 | H27: =IF($G$48="ERRO","ERRO",IF($G$48=0,0,G27/$G$48)) -> 0 | J27: =IF($I$48="ERRO","ERRO",IF($I$48=0,0,I27/$I$48)) -> 0
B29: REALIZ. L.P. | C29: =SUM(C30:C40) -> 0 | D29: =IF($C$48="ERRO","ERRO",IF($C$48=0,0,C29/$C$48)) -> 0 | E29: =SUM(E30:E40) -> 0 | F29: =IF($E$48="ERRO","ERRO",IF($E$48=0,0,E29/$E$48)) -> 0 | G29: =SUM(G30:G40) -> 0 | H29: =IF($G$48="ERRO","ERRO",IF($G$48=0,0,G29/$G$48)) -> 0 | I29: =SUM(I30:I40) -> 0 | J29: =IF($I$48="ERRO","ERRO",IF($I$48=0,0,I29/$I$48)) -> 0
B30: Contas a Receber | D30: =IF($C$48="ERRO","ERRO",IF($C$48=0,0,C30/$C$48)) -> 0 | F30: =IF($E$48="ERRO","ERRO",IF($E$48=0,0,E30/$E$48)) -> 0 | H30: =IF($G$48="ERRO","ERRO",IF($G$48=0,0,G30/$G$48)) -> 0 | J30: =IF($I$48="ERRO","ERRO",IF($I$48=0,0,I30/$I$48)) -> 0
B31: Cooperados | D31: =IF($C$48="ERRO","ERRO",IF($C$48=0,0,C31/$C$48)) -> 0 | F31: =IF($E$48="ERRO","ERRO",IF($E$48=0,0,E31/$E$48)) -> 0 | H31: =IF($G$48="ERRO","ERRO",IF($G$48=0,0,G31/$G$48)) -> 0 | J31: =IF($I$48="ERRO","ERRO",IF($I$48=0,0,I31/$I$48)) -> 0
B32: C/C Coligadas/Acionistas | D32: =IF($C$48="ERRO","ERRO",IF($C$48=0,0,C32/$C$48)) -> 0 | F32: =IF($E$48="ERRO","ERRO",IF($E$48=0,0,E32/$E$48)) -> 0 | H32: =IF($G$48="ERRO","ERRO",IF($G$48=0,0,G32/$G$48)) -> 0 | J32: =IF($I$48="ERRO","ERRO",IF($I$48=0,0,I32/$I$48)) -> 0
B33: Depósitos Judiciais | D33: =IF($C$48="ERRO","ERRO",IF($C$48=0,0,C33/$C$48)) -> 0 | F33: =IF($E$48="ERRO","ERRO",IF($E$48=0,0,E33/$E$48)) -> 0 | H33: =IF($G$48="ERRO","ERRO",IF($G$48=0,0,G33/$G$48)) -> 0 | J33: =IF($I$48="ERRO","ERRO",IF($I$48=0,0,I33/$I$48)) -> 0
B34: Imposto Diferido | D34: =IF($C$48="ERRO","ERRO",IF($C$48=0,0,C34/$C$48)) -> 0 | F34: =IF($E$48="ERRO","ERRO",IF($E$48=0,0,E34/$E$48)) -> 0 | H34: =IF($G$48="ERRO","ERRO",IF($G$48=0,0,G34/$G$48)) -> 0 | J34: =IF($I$48="ERRO","ERRO",IF($I$48=0,0,I34/$I$48)) -> 0
B35: Créditos a Fumicultores | D35: =IF($C$48="ERRO","ERRO",IF($C$48=0,0,C35/$C$48)) -> 0 | F35: =IF($E$48="ERRO","ERRO",IF($E$48=0,0,E35/$E$48)) -> 0 | H35: =IF($G$48="ERRO","ERRO",IF($G$48=0,0,G35/$G$48)) -> 0 | J35: =IF($I$48="ERRO","ERRO",IF($I$48=0,0,I35/$I$48)) -> 0
B36: CTN´s | D36: =IF($C$48="ERRO","ERRO",IF($C$48=0,0,C36/$C$48)) -> 0 | F36: =IF($E$48="ERRO","ERRO",IF($E$48=0,0,E36/$E$48)) -> 0 | H36: =IF($G$48="ERRO","ERRO",IF($G$48=0,0,G36/$G$48)) -> 0 | J36: =IF($I$48="ERRO","ERRO",IF($I$48=0,0,I36/$I$48)) -> 0
B37: Outros Operac. | D37: =IF($C$48="ERRO","ERRO",IF($C$48=0,0,C37/$C$48)) -> 0 | F37: =IF($E$48="ERRO","ERRO",IF($E$48=0,0,E37/$E$48)) -> 0 | H37: =IF($G$48="ERRO","ERRO",IF($G$48=0,0,G37/$G$48)) -> 0 | J37: =IF($I$48="ERRO","ERRO",IF($I$48=0,0,I37/$I$48)) -> 0
B38: Outros Operac. | D38: =IF($C$48="ERRO","ERRO",IF($C$48=0,0,C38/$C$48)) -> 0 | F38: =IF($E$48="ERRO","ERRO",IF($E$48=0,0,E38/$E$48)) -> 0 | H38: =IF($G$48="ERRO","ERRO",IF($G$48=0,0,G38/$G$48)) -> 0 | J38: =IF($I$48="ERRO","ERRO",IF($I$48=0,0,I38/$I$48)) -> 0
B39: Outros Nao Operac. | D39: =IF($C$48="ERRO","ERRO",IF($C$48=0,0,C39/$C$48)) -> 0 | F39: =IF($E$48="ERRO","ERRO",IF($E$48=0,0,E39/$E$48)) -> 0 | H39: =IF($G$48="ERRO","ERRO",IF($G$48=0,0,G39/$G$48)) -> 0 | J39: =IF($I$48="ERRO","ERRO",IF($I$48=0,0,I39/$I$48)) -> 0
B40: Outros Nao Operac. | D40: =IF($C$48="ERRO","ERRO",IF($C$48=0,0,C40/$C$48)) -> 0 | F40: =IF($E$48="ERRO","ERRO",IF($E$48=0,0,E40/$E$48)) -> 0 | H40: =IF($G$48="ERRO","ERRO",IF($G$48=0,0,G40/$G$48)) -> 0 | J40: =IF($I$48="ERRO","ERRO",IF($I$48=0,0,I40/$I$48)) -> 0
B42: PERMANENTE | C42: =SUM(C43:C45) -> 0 | D42: =IF($C$48="ERRO","ERRO",IF($C$48=0,0,C42/$C$48)) -> 0 | E42: =SUM(E43:E45) -> 0 | F42: =IF($E$48="ERRO","ERRO",IF($E$48=0,0,E42/$E$48)) -> 0 | G42: =SUM(G43:G45) -> 0 | H42: =IF($G$48="ERRO","ERRO",IF($G$48=0,0,G42/$G$48)) -> 0 | I42: =SUM(I43:I45) -> 0 | J42: =IF($I$48="ERRO","ERRO",IF($I$48=0,0,I42/$I$48)) -> 0
B43: Imobilizado Técnico | D43: =IF($C$48="ERRO","ERRO",IF($C$48=0,0,C43/$C$48)) -> 0 | F43: =IF($E$48="ERRO","ERRO",IF($E$48=0,0,E43/$E$48)) -> 0 | H43: =IF($G$48="ERRO","ERRO",IF($G$48=0,0,G43/$G$48)) -> 0 | J43: =IF($I$48="ERRO","ERRO",IF($I$48=0,0,I43/$I$48)) -> 0
B44: Investimentos | D44: =IF($C$48="ERRO","ERRO",IF($C$48=0,0,C44/$C$48)) -> 0 | F44: =IF($E$48="ERRO","ERRO",IF($E$48=0,0,E44/$E$48)) -> 0 | H44: =IF($G$48="ERRO","ERRO",IF($G$48=0,0,G44/$G$48)) -> 0 | J44: =IF($I$48="ERRO","ERRO",IF($I$48=0,0,I44/$I$48)) -> 0
B45: Diferido/Intangível | D45: =IF($C$48="ERRO","ERRO",IF($C$48=0,0,C45/$C$48)) -> 0 | F45: =IF($E$48="ERRO","ERRO",IF($E$48=0,0,E45/$E$48)) -> 0 | H45: =IF($G$48="ERRO","ERRO",IF($G$48=0,0,G45/$G$48)) -> 0 | J45: =IF($I$48="ERRO","ERRO",IF($I$48=0,0,I45/$I$48)) -> 0
B47: TOTAL | C47: =IF(OR(C11+C29+C42-C51-C79-C97-C99-C101>1,C11+C29+C42-C51-C79-C97-C99-C101<-1),"ERRO",C11+C29+C42) -> 0 | D47: =IF($C$48="ERRO","ERRO",IF($C$48=0,0,C47/$C$48)) -> 0 | E47: =IF(OR(E11+E29+E42-E51-E79-E97-E99-E101>1,E11+E29+E42-E51-E79-E97-E99-E101<-1),"ERRO",E11+E29+E42) -> 0 | F47: =IF($E$48="ERRO","ERRO",IF($E$48=0,0,E47/$E$48)) -> 0 | G47: =IF(OR(G11+G29+G42-G51-G79-G97-G99-G101>1,G11+G29+G42-G51-G79-G97-G99-G101<-1),"ERRO",G11+G29+G42) -> 0 | H47: =IF($G$48="ERRO","ERRO",IF($G$48=0,0,G47/$G$48)) -> 0 | I47: =IF(OR(I11+I29+I42-I51-I79-I97-I99-I101>1,I11+I29+I42-I51-I79-I97-I99-I101<-1),"ERRO",I11+I29+I42) -> 0 | J47: =IF($I$48="ERRO","ERRO",IF($I$48=0,0,I47/$I$48)) -> 0
B49: PASSIVO | C49: R$ MIL | D49: (%) | E49: R$ MIL | F49: (%) | G49: R$ MIL | H49: (%) | I49: R$ MIL | J49: (%)
B51: CIRCULANTE | C51: =SUM(C52:C77) -> 0 | D51: =IF($C$48="ERRO","ERRO",IF($C$48=0,0,C51/$C$48)) -> 0 | E51: =SUM(E52:E77) -> 0 | F51: =IF($E$48="ERRO","ERRO",IF($E$48=0,0,E51/$E$48)) -> 0 | G51: =SUM(G52:G77) -> 0 | H51: =IF($G$48="ERRO","ERRO",IF($G$48=0,0,G51/$G$48)) -> 0 | I51: =SUM(I52:I77) -> 0 | J51: =IF($I$48="ERRO","ERRO",IF($I$48=0,0,I51/$I$48)) -> 0
...

Sheet CONSOLIDADO
B1: TOTAL ATIVO | C1: =SUM(C11+C29+C42) -> 0 | E1: =SUM(E11+E29+E42) -> 0 | G1: =SUM(G11+G29+G42) -> 0 | I1: =SUM(I11+I29+I42) -> 0
B2: TOTAL PASSIVO | C2: =C51+C79+C97+C99+C101 -> 0 | E2: =E51+E79+E97+E99+E101 -> 0 | G2: =G51+G79+G97+G99+G101 -> 0 | I2: =I51+I79+I97+I99+I101 -> 0
B3: DIFERENÇA | C3: =C1-C2 -> 0 | E3: =E1-E2 -> 0 | G3: =G1-G2 -> 0 | I3: =I1-I2 -> 0
B5: GRUPO ECONOMICO 1
B7: BALANÇO PATRIMONIAL
C8: 44896 | E8: 45261 | G8: 45627 | I8: 45992
B9: ATIVO | C9: R$ MIL | D9: (%) | E9: R$ MIL | F9: (%) | G9: R$ MIL | H9: (%) | I9: R$ MIL | J9: (%)
B11: CIRCULANTE | C11: =SUM(C12:C27) -> 0 | D11: =IF($D$48="ERRO","ERRO",IF($D$48=0,0,C11/$D$48)) -> 0 | E11: =SUM(E12:E27) -> 0 | F11: =IF($F$48="ERRO","ERRO",IF($F$48=0,0,E11/$F$48)) -> 0 | G11: =SUM(G12:G27) -> 0 | H11: =IF($H$48="ERRO","ERRO",IF($H$48=0,0,G11/$H$48)) -> 0 | I11: =SUM(I12:I27) -> 0 | J11: =IF($J$48="ERRO","ERRO",IF($J$48=0,0,I11/$J$48)) -> 0
B12: Caixa e Bancos | C12: =SUM(EMP_1!C12+EMP_2!C12) -> 0 | D12: =IF($D$48="ERRO","ERRO",IF($D$48=0,0,C12/$D$48)) -> 0 | E12: =SUM(EMP_1!E12+EMP_2!E12) -> 0 | F12: =IF($F$48="ERRO","ERRO",IF($F$48=0,0,E12/$F$48)) -> 0 | G12: =SUM(EMP_1!G12+EMP_2!G12) -> 0 | H12: =IF($H$48="ERRO","ERRO",IF($H$48=0,0,G12/$H$48)) -> 0 | I12: =SUM(EMP_1!I12+EMP_2!I12) -> 0 | J12: =IF($J$48="ERRO","ERRO",IF($J$48=0,0,I12/$J$48)) -> 0
B13: Aplicações Financeiras | C13: =SUM(EMP_1!C13+EMP_2!C13) -> 0 | D13: =IF($D$48="ERRO","ERRO",IF($D$48=0,0,C13/$D$48)) -> 0 | E13: =SUM(EMP_1!E13+EMP_2!E13) -> 0 | F13: =IF($F$48="ERRO","ERRO",IF($F$48=0,0,E13/$F$48)) -> 0 | G13: =SUM(EMP_1!G13+EMP_2!G13) -> 0 | H13: =IF($H$48="ERRO","ERRO",IF($H$48=0,0,G13/$H$48)) -> 0 | I13: =SUM(EMP_1!I13+EMP_2!I13) -> 0 | J13: =IF($J$48="ERRO","ERRO",IF($J$48=0,0,I13/$J$48)) -> 0
B14: Contas a Receber | C14: 0 | D14: =IF($D$48="ERRO","ERRO",IF($D$48=0,0,C14/$D$48)) -> 0 | E14: 0 | F14: =IF($F$48="ERRO","ERRO",IF($F$48=0,0,E14/$F$48)) -> 0 | G14: =SUM(EMP_1!G14+EMP_2!G14) -> 0 | H14: =IF($H$48="ERRO","ERRO",IF($H$48=0,0,G14/$H$48)) -> 0 | I14: =SUM(EMP_1!I14+EMP_2!I14) -> 0 | J14: =IF($J$48="ERRO","ERRO",IF($J$48=0,0,I14/$J$48)) -> 0
B15: Cooperados | C15: =SUM(EMP_1!C15+EMP_2!C15) -> 0 | D15: =IF($D$48="ERRO","ERRO",IF($D$48=0,0,C15/$D$48)) -> 0 | E15: =SUM(EMP_1!E15+EMP_2!E15) -> 0 | F15: =IF($F$48="ERRO","ERRO",IF($F$48=0,0,E15/$F$48)) -> 0 | G15: =SUM(EMP_1!G15+EMP_2!G15) -> 0 | H15: =IF($H$48="ERRO","ERRO",IF($H$48=0,0,G15/$H$48)) -> 0 | I15: =SUM(EMP_1!I15+EMP_2!I15) -> 0 | J15: =IF($J$48="ERRO","ERRO",IF($J$48=0,0,I15/$J$48)) -> 0
B16: CVA | C16: =SUM(EMP_1!C16+EMP_2!C16) -> 0 | D16: =IF($D$48="ERRO","ERRO",IF($D$48=0,0,C16/$D$48)) -> 0 | E16: =SUM(EMP_1!E16+EMP_2!E16) -> 0 | F16: =IF($F$48="ERRO","ERRO",IF($F$48=0,0,E16/$F$48)) -> 0 | G16: =SUM(EMP_1!G16+EMP_2!G16) -> 0 | H16: =IF($H$48="ERRO","ERRO",IF($H$48=0,0,G16/$H$48)) -> 0 | I16: =SUM(EMP_1!I16+EMP_2!I16) -> 0 | J16: =IF($J$48="ERRO","ERRO",IF($J$48=0,0,I16/$J$48)) -> 0
B17: Estoques | C17: =SUM(EMP_1!C17+EMP_2!C17) -> 0 | D17: =IF($D$48="ERRO","ERRO",IF($D$48=0,0,C17/$D$48)) -> 0 | E17: =SUM(EMP_1!E17+EMP_2!E17) -> 0 | F17: =IF($F$48="ERRO","ERRO",IF($F$48=0,0,E17/$F$48)) -> 0 | G17: =SUM(EMP_1!G17+EMP_2!G17) -> 0 | H17: =IF($H$48="ERRO","ERRO",IF($H$48=0,0,G17/$H$48)) -> 0 | I17: =SUM(EMP_1!I17+EMP_2!I17) -> 0 | J17: =IF($J$48="ERRO","ERRO",IF($J$48=0,0,I17/$J$48)) -> 0
B18: Adiant. a Fornecedores | C18: =SUM(EMP_1!C18+EMP_2!C18) -> 0 | D18: =IF($D$48="ERRO","ERRO",IF($D$48=0,0,C18/$D$48)) -> 0 | E18: =SUM(EMP_1!E18+EMP_2!E18) -> 0 | F18: =IF($F$48="ERRO","ERRO",IF($F$48=0,0,E18/$F$48)) -> 0 | G18: =SUM(EMP_1!G18+EMP_2!G18) -> 0 | H18: =IF($H$48="ERRO","ERRO",IF($H$48=0,0,G18/$H$48)) -> 0 | I18: =SUM(EMP_1!I18+EMP_2!I18) -> 0 | J18: =IF($J$48="ERRO","ERRO",IF($J$48=0,0,I18/$J$48)) -> 0
B19: Créditos a Fumicultores | C19: =SUM(EMP_1!C19+EMP_2!C19) -> 0 | D19: =IF($D$48="ERRO","ERRO",IF($D$48=0,0,C19/$D$48)) -> 0 | E19: =SUM(EMP_1!E19+EMP_2!E19) -> 0 | F19: =IF($F$48="ERRO","ERRO",IF($F$48=0,0,E19/$F$48)) -> 0 | G19: =SUM(EMP_1!G19+EMP_2!G19) -> 0 | H19: =IF($H$48="ERRO","ERRO",IF($H$48=0,0,G19/$H$48)) -> 0 | I19: =SUM(EMP_1!I19+EMP_2!I19) -> 0 | J19: =IF($J$48="ERRO","ERRO",IF($J$48=0,0,I19/$J$48)) -> 0
B20: Despesas Antecipadas | C20: =SUM(EMP_1!C20+EMP_2!C20) -> 0 | D20: =IF($D$48="ERRO","ERRO",IF($D$48=0,0,C20/$D$48)) -> 0 | E20: =SUM(EMP_1!E20+EMP_2!E20) -> 0 | F20: =IF($F$48="ERRO","ERRO",IF($F$48=0,0,E20/$F$48)) -> 0 | G20: =SUM(EMP_1!G20+EMP_2!G20) -> 0 | H20: =IF($H$48="ERRO","ERRO",IF($H$48=0,0,G20/$H$48)) -> 0 | I20: =SUM(EMP_1!I20+EMP_2!I20) -> 0 | J20: =IF($J$48="ERRO","ERRO",IF($J$48=0,0,I20/$J$48)) -> 0
B21: Impostos a Recuperar | C21: =SUM(EMP_1!C21+EMP_2!C21) -> 0 | D21: =IF($D$48="ERRO","ERRO",IF($D$48=0,0,C21/$D$48)) -> 0 | E21: =SUM(EMP_1!E21+EMP_2!E21) -> 0 | F21: =IF($F$48="ERRO","ERRO",IF($F$48=0,0,E21/$F$48)) -> 0 | G21: =SUM(EMP_1!G21+EMP_2!G21) -> 0 | H21: =IF($H$48="ERRO","ERRO",IF($H$48=0,0,G21/$H$48)) -> 0 | I21: =SUM(EMP_1!I21+EMP_2!I21) -> 0 | J21: =IF($J$48="ERRO","ERRO",IF($J$48=0,0,I21/$J$48)) -> 0
B22: Dividendos a Receber | C22: =SUM(EMP_1!C22+EMP_2!C22) -> 0 | D22: =IF($D$48="ERRO","ERRO",IF($D$48=0,0,C22/$D$48)) -> 0 | E22: =SUM(EMP_1!E22+EMP_2!E22) -> 0 | F22: =IF($F$48="ERRO","ERRO",IF($F$48=0,0,E22/$F$48)) -> 0 | G22: =SUM(EMP_1!G22+EMP_2!G22) -> 0 | H22: =IF($H$48="ERRO","ERRO",IF($H$48=0,0,G22/$H$48)) -> 0 | I22: =SUM(EMP_1!I22+EMP_2!I22) -> 0 | J22: =IF($J$48="ERRO","ERRO",IF($J$48=0,0,I22/$J$48)) -> 0
B23: Imposto Diferido | C23: =SUM(EMP_1!C23+EMP_2!C23) -> 0 | D23: =IF($D$48="ERRO","ERRO",IF($D$48=0,0,C23/$D$48)) -> 0 | E23: =SUM(EMP_1!E23+EMP_2!E23) -> 0 | F23: =IF($F$48="ERRO","ERRO",IF($F$48=0,0,E23/$F$48)) -> 0 | G23: =SUM(EMP_1!G23+EMP_2!G23) -> 0 | H23: =IF($H$48="ERRO","ERRO",IF($H$48=0,0,G23/$H$48)) -> 0 | I23: =SUM(EMP_1!I23+EMP_2!I23) -> 0 | J23: =IF($J$48="ERRO","ERRO",IF($J$48=0,0,I23/$J$48)) -> 0
B24: Outros Operac. | C24: =SUM(EMP_1!C24+EMP_2!C24) -> 0 | D24: =IF($D$48="ERRO","ERRO",IF($D$48=0,0,C24/$D$48)) -> 0 | E24: =SUM(EMP_1!E24+EMP_2!E24) -> 0 | F24: =IF($F$48="ERRO","ERRO",IF($F$48=0,0,E24/$F$48)) -> 0 | G24: =SUM(EMP_1!G24+EMP_2!G24) -> 0 | H24: =IF($H$48="ERRO","ERRO",IF($H$48=0,0,G24/$H$48)) -> 0 | I24: =SUM(EMP_1!I24+EMP_2!I24) -> 0 | J24: =IF($J$48="ERRO","ERRO",IF($J$48=0,0,I24/$J$48)) -> 0
B25: Outros Operac. | C25: =SUM(EMP_1!C25+EMP_2!C25) -> 0 | D25: =IF($D$48="ERRO","ERRO",IF($D$48=0,0,C25/$D$48)) -> 0 | E25: =SUM(EMP_1!E25+EMP_2!E25) -> 0 | F25: =IF($F$48="ERRO","ERRO",IF($F$48=0,0,E25/$F$48)) -> 0 | G25: =SUM(EMP_1!G25+EMP_2!G25) -> 0 | H25: =IF($H$48="ERRO","ERRO",IF($H$48=0,0,G25/$H$48)) -> 0 | I25: =SUM(EMP_1!I25+EMP_2!I25) -> 0 | J25: =IF($J$48="ERRO","ERRO",IF($J$48=0,0,I25/$J$48)) -> 0
B26: Outros Nao Operac. | C26: =SUM(EMP_1!C26+EMP_2!C26) -> 0 | D26: =IF($D$48="ERRO","ERRO",IF($D$48=0,0,C26/$D$48)) -> 0 | E26: =SUM(EMP_1!E26+EMP_2!E26) -> 0 | F26: =IF($F$48="ERRO","ERRO",IF($F$48=0,0,E26/$F$48)) -> 0 | G26: =SUM(EMP_1!G26+EMP_2!G26) -> 0 | H26: =IF($H$48="ERRO","ERRO",IF($H$48=0,0,G26/$H$48)) -> 0 | I26: =SUM(EMP_1!I26+EMP_2!I26) -> 0 | J26: =IF($J$48="ERRO","ERRO",IF($J$48=0,0,I26/$J$48)) -> 0
B27: Outros Nao Operac. | C27: =SUM(EMP_1!C27+EMP_2!C27) -> 0 | D27: =IF($D$48="ERRO","ERRO",IF($D$48=0,0,C27/$D$48)) -> 0 | E27: =SUM(EMP_1!E27+EMP_2!E27) -> 0 | F27: =IF($F$48="ERRO","ERRO",IF($F$48=0,0,E27/$F$48)) -> 0 | G27: =SUM(EMP_1!G27+EMP_2!G27) -> 0 | H27: =IF($H$48="ERRO","ERRO",IF($H$48=0,0,G27/$H$48)) -> 0 | I27: =SUM(EMP_1!I27+EMP_2!I27) -> 0 | J27: =IF($J$48="ERRO","ERRO",IF($J$48=0,0,I27/$J$48)) -> 0
B29: REALIZ. L.P. | C29: =SUM(C30:C40) -> 0 | D29: =IF($D$48="ERRO","ERRO",IF($D$48=0,0,C29/$D$48)) -> 0 | E29: =SUM(E30:E40) -> 0 | F29: =IF($F$48="ERRO","ERRO",IF($F$48=0,0,E29/$F$48)) -> 0 | G29: =SUM(G30:G40) -> 0 | H29: =IF($H$48="ERRO","ERRO",IF($H$48=0,0,G29/$H$48)) -> 0 | I29: =SUM(I30:I40) -> 0 | J29: =IF($J$48="ERRO","ERRO",IF($J$48=0,0,I29/$J$48)) -> 0
B30: Contas a Receber | C30: =SUM(EMP_1!C30+EMP_2!C30) -> 0 | D30: =IF($D$48="ERRO","ERRO",IF($D$48=0,0,C30/$D$48)) -> 0 | E30: =SUM(EMP_1!E30+EMP_2!E30) -> 0 | F30: =IF($F$48="ERRO","ERRO",IF($F$48=0,0,E30/$F$48)) -> 0 | G30: =SUM(EMP_1!G30+EMP_2!G30) -> 0 | H30: =IF($H$48="ERRO","ERRO",IF($H$48=0,0,G30/$H$48)) -> 0 | I30: =SUM(EMP_1!I30+EMP_2!I30) -> 0 | J30: =IF($J$48="ERRO","ERRO",IF($J$48=0,0,I30/$J$48)) -> 0
B31: Cooperados | C31: =SUM(EMP_1!C31+EMP_2!C31) -> 0 | D31: =IF($D$48="ERRO","ERRO",IF($D$48=0,0,C31/$D$48)) -> 0 | E31: =SUM(EMP_1!E31+EMP_2!E31) -> 0 | F31: =IF($F$48="ERRO","ERRO",IF($F$48=0,0,E31/$F$48)) -> 0 | G31: =SUM(EMP_1!G31+EMP_2!G31) -> 0 | H31: =IF($H$48="ERRO","ERRO",IF($H$48=0,0,G31/$H$48)) -> 0 | I31: =SUM(EMP_1!I31+EMP_2!I31) -> 0 | J31: =IF($J$48="ERRO","ERRO",IF($J$48=0,0,I31/$J$48)) -> 0
B32: C/C Coligadas/Acionistas | C32: =SUM(EMP_1!C32+EMP_2!C32) -> 0 | D32: =IF($D$48="ERRO","ERRO",IF($D$48=0,0,C32/$D$48)) -> 0 | E32: =SUM(EMP_1!E32+EMP_2!E32) -> 0 | F32: =IF($F$48="ERRO","ERRO",IF($F$48=0,0,E32/$F$48)) -> 0 | G32: =SUM(EMP_1!G32+EMP_2!G32) -> 0 | H32: =IF($H$48="ERRO","ERRO",IF($H$48=0,0,G32/$H$48)) -> 0 | I32: =SUM(EMP_1!I32+EMP_2!I32) -> 0 | J32: =IF($J$48="ERRO","ERRO",IF($J$48=0,0,I32/$J$48)) -> 0
B33: Depósitos Judiciais | C33: =SUM(EMP_1!C33+EMP_2!C33) -> 0 | D33: =IF($D$48="ERRO","ERRO",IF($D$48=0,0,C33/$D$48)) -> 0 | E33: =SUM(EMP_1!E33+EMP_2!E33) -> 0 | F33: =IF($F$48="ERRO","ERRO",IF($F$48=0,0,E33/$F$48)) -> 0 | G33: =SUM(EMP_1!G33+EMP_2!G33) -> 0 | H33: =IF($H$48="ERRO","ERRO",IF($H$48=0,0,G33/$H$48)) -> 0 | I33: =SUM(EMP_1!I33+EMP_2!I33) -> 0 | J33: =IF($J$48="ERRO","ERRO",IF($J$48=0,0,I33/$J$48)) -> 0
B34: Imposto Diferido | C34: =SUM(EMP_1!C34+EMP_2!C34) -> 0 | D34: =IF($D$48="ERRO","ERRO",IF($D$48=0,0,C34/$D$48)) -> 0 | E34: =SUM(EMP_1!E34+EMP_2!E34) -> 0 | F34: =IF($F$48="ERRO","ERRO",IF($F$48=0,0,E34/$F$48)) -> 0 | G34: =SUM(EMP_1!G34+EMP_2!G34) -> 0 | H34: =IF($H$48="ERRO","ERRO",IF($H$48=0,0,G34/$H$48)) -> 0 | I34: =SUM(EMP_1!I34+EMP_2!I34) -> 0 | J34: =IF($J$48="ERRO","ERRO",IF($J$48=0,0,I34/$J$48)) -> 0
B35: Créditos a Fumicultores | C35: =SUM(EMP_1!C35+EMP_2!C35) -> 0 | D35: =IF($D$48="ERRO","ERRO",IF($D$48=0,0,C35/$D$48)) -> 0 | E35: =SUM(EMP_1!E35+EMP_2!E35) -> 0 | F35: =IF($F$48="ERRO","ERRO",IF($F$48=0,0,E35/$F$48)) -> 0 | G35: =SUM(EMP_1!G35+EMP_2!G35) -> 0 | H35: =IF($H$48="ERRO","ERRO",IF($H$48=0,0,G35/$H$48)) -> 0 | I35: =SUM(EMP_1!I35+EMP_2!I35) -> 0 | J35: =IF($J$48="ERRO","ERRO",IF($J$48=0,0,I35/$J$48)) -> 0
B36: CTN´s | C36: =SUM(EMP_1!C36+EMP_2!C36) -> 0 | D36: =IF($D$48="ERRO","ERRO",IF($D$48=0,0,C36/$D$48)) -> 0 | E36: =SUM(EMP_1!E36+EMP_2!E36) -> 0 | F36: =IF($F$48="ERRO","ERRO",IF($F$48=0,0,E36/$F$48)) -> 0 | G36: =SUM(EMP_1!G36+EMP_2!G36) -> 0 | H36: =IF($H$48="ERRO","ERRO",IF($H$48=0,0,G36/$H$48)) -> 0 | I36: =SUM(EMP_1!I36+EMP_2!I36) -> 0 | J36: =IF($J$48="ERRO","ERRO",IF($J$48=0,0,I36/$J$48)) -> 0
B37: Outros Operac. | C37: =SUM(EMP_1!C37+EMP_2!C37) -> 0 | D37: =IF($D$48="ERRO","ERRO",IF($D$48=0,0,C37/$D$48)) -> 0 | E37: =SUM(EMP_1!E37+EMP_2!E37) -> 0 | F37: =IF($F$48="ERRO","ERRO",IF($F$48=0,0,E37/$F$48)) -> 0 | G37: =SUM(EMP_1!G37+EMP_2!G37) -> 0 | H37: =IF($H$48="ERRO","ERRO",IF($H$48=0,0,G37/$H$48)) -> 0 | I37: =SUM(EMP_1!I37+EMP_2!I37) -> 0 | J37: =IF($J$48="ERRO","ERRO",IF($J$48=0,0,I37/$J$48)) -> 0
B38: Outros Operac. | C38: =SUM(EMP_1!C38+EMP_2!C38) -> 0 | D38: =IF($D$48="ERRO","ERRO",IF($D$48=0,0,C38/$D$48)) -> 0 | E38: =SUM(EMP_1!E38+EMP_2!E38) -> 0 | F38: =IF($F$48="ERRO","ERRO",IF($F$48=0,0,E38/$F$48)) -> 0 | G38: =SUM(EMP_1!G38+EMP_2!G38) -> 0 | H38: =IF($H$48="ERRO","ERRO",IF($H$48=0,0,G38/$H$48)) -> 0 | I38: =SUM(EMP_1!I38+EMP_2!I38) -> 0 | J38: =IF($J$48="ERRO","ERRO",IF($J$48=0,0,I38/$J$48)) -> 0
B39: Outros Nao Operac. | C39: =SUM(EMP_1!C39+EMP_2!C39) -> 0 | D39: =IF($D$48="ERRO","ERRO",IF($D$48=0,0,C39/$D$48)) -> 0 | E39: =SUM(EMP_1!E39+EMP_2!E39) -> 0 | F39: =IF($F$48="ERRO","ERRO",IF($F$48=0,0,E39/$F$48)) -> 0 | G39: =SUM(EMP_1!G39+EMP_2!G39) -> 0 | H39: =IF($H$48="ERRO","ERRO",IF($H$48=0,0,G39/$H$48)) -> 0 | I39: =SUM(EMP_1!I39+EMP_2!I39) -> 0 | J39: =IF($J$48="ERRO","ERRO",IF($J$48=0,0,I39/$J$48)) -> 0
B40: Outros Nao Operac. | C40: =SUM(EMP_1!C40+EMP_2!C40) -> 0 | D40: =IF($D$48="ERRO","ERRO",IF($D$48=0,0,C40/$D$48)) -> 0 | E40: =SUM(EMP_1!E40+EMP_2!E40) -> 0 | F40: =IF($F$48="ERRO","ERRO",IF($F$48=0,0,E40/$F$48)) -> 0 | G40: =SUM(EMP_1!G40+EMP_2!G40) -> 0 | H40: =IF($H$48="ERRO","ERRO",IF($H$48=0,0,G40/$H$48)) -> 0 | I40: =SUM(EMP_1!I40+EMP_2!I40) -> 0 | J40: =IF($J$48="ERRO","ERRO",IF($J$48=0,0,I40/$J$48)) -> 0
B42: PERMANENTE | C42: =SUM(C43:C45) -> 0 | D42: =IF($D$48="ERRO","ERRO",IF($D$48=0,0,C42/$D$48)) -> 0 | E42: =SUM(E43:E45) -> 0 | F42: =IF($F$48="ERRO","ERRO",IF($F$48=0,0,E42/$F$48)) -> 0 | G42: =SUM(G43:G45) -> 0 | H42: =IF($H$48="ERRO","ERRO",IF($H$48=0,0,G42/$H$48)) -> 0 | I42: =SUM(I43:I45) -> 0 | J42: =IF($J$48="ERRO","ERRO",IF($J$48=0,0,I42/$J$48)) -> 0
B43: Imobilizado Técnico | C43: =SUM(EMP_1!C43+EMP_2!C43) -> 0 | D43: =IF($D$48="ERRO","ERRO",IF($D$48=0,0,C43/$D$48)) -> 0 | E43: =SUM(EMP_1!E43+EMP_2!E43) -> 0 | F43: =IF($F$48="ERRO","ERRO",IF($F$48=0,0,E43/$F$48)) -> 0 | G43: =SUM(EMP_1!G43+EMP_2!G43) -> 0 | H43: =IF($H$48="ERRO","ERRO",IF($H$48=0,0,G43/$H$48)) -> 0 | I43: =SUM(EMP_1!I43+EMP_2!I43) -> 0 | J43: =IF($J$48="ERRO","ERRO",IF($J$48=0,0,I43/$J$48)) -> 0
B44: Investimentos | C44: =SUM(EMP_1!C44+EMP_2!C44) -> 0 | D44: =IF($D$48="ERRO","ERRO",IF($D$48=0,0,C44/$D$48)) -> 0 | E44: =SUM(EMP_1!E44+EMP_2!E44) -> 0 | F44: =IF($F$48="ERRO","ERRO",IF($F$48=0,0,E44/$F$48)) -> 0 | G44: =SUM(EMP_1!G44+EMP_2!G44) -> 0 | H44: =IF($H$48="ERRO","ERRO",IF($H$48=0,0,G44/$H$48)) -> 0 | I44: =SUM(EMP_1!I44+EMP_2!I44) -> 0 | J44: =IF($J$48="ERRO","ERRO",IF($J$48=0,0,I44/$J$48)) -> 0
B45: Diferido/Intangível | C45: =SUM(EMP_1!C45+EMP_2!C45) -> 0 | D45: =IF($D$48="ERRO","ERRO",IF($D$48=0,0,C45/$D$48)) -> 0 | E45: =SUM(EMP_1!E45+EMP_2!E45) -> 0 | F45: =IF($F$48="ERRO","ERRO",IF($F$48=0,0,E45/$F$48)) -> 0 | G45: =SUM(EMP_1!G45+EMP_2!G45) -> 0 | H45: =IF($H$48="ERRO","ERRO",IF($H$48=0,0,G45/$H$48)) -> 0 | I45: =SUM(EMP_1!I45+EMP_2!I45) -> 0 | J45: =IF($J$48="ERRO","ERRO",IF($J$48=0,0,I45/$J$48)) -> 0
...

Sheet HIGHLIGHTS
B1: 44896 | C1: A.V. % | D1: 45261 | E1: A.V. % | F1: 45627 | G1: A.V. % | H1: 45992 | I1: A.V. %
A2: RECEITA BRUTA | B2: =CONSOLIDADO!C111 -> 0 | C2: =B2/$B$2 -> #DIV/0! | D2: =CONSOLIDADO!E111 -> 0 | E2: =D2/$D$2 -> #DIV/0! | F2: =CONSOLIDADO!G111 -> 0 | G2: =F2/$F$2 -> #DIV/0! | H2: =CONSOLIDADO!I111 -> 0 | I2: =H2/$H$2 -> #DIV/0!
A3: RECEITA LÍQUIDA | B3: =CONSOLIDADO!C113 -> 0 | C3: =B3/$B$2 -> #DIV/0! | D3: =CONSOLIDADO!E113 -> 0 | E3: =D3/$D$2 -> #DIV/0! | F3: =CONSOLIDADO!G113 -> 0 | G3: =F3/$F$2 -> #DIV/0! | H3: =CONSOLIDADO!I113 -> 0 | I3: =H3/$H$2 -> #DIV/0!
A4: RESULTADO BRUTO | B4: =CONSOLIDADO!C119 -> 0 | C4: =B4/$B$2 -> #DIV/0! | D4: =CONSOLIDADO!E119 -> 0 | E4: =D4/$D$2 -> #DIV/0! | F4: =CONSOLIDADO!G119 -> 0 | G4: =F4/$F$2 -> #DIV/0! | H4: =CONSOLIDADO!I119 -> 0 | I4: =H4/$H$2 -> #DIV/0!
A5: RESULTADO ATIVIDADE | B5: =CONSOLIDADO!C124 -> 0 | C5: =B5/$B$2 -> #DIV/0! | D5: =CONSOLIDADO!E124 -> 0 | E5: =D5/$D$2 -> #DIV/0! | F5: =CONSOLIDADO!G124 -> 0 | G5: =F5/$F$2 -> #DIV/0! | H5: =CONSOLIDADO!I124 -> 0 | I5: =H5/$H$2 -> #DIV/0!
A6: RESULTADO LÍQUIDO | B6: =CONSOLIDADO!C139 -> 0 | C6: =B6/$B$2 -> #DIV/0! | D6: =CONSOLIDADO!E139 -> 0 | E6: =D6/$D$2 -> #DIV/0! | F6: =CONSOLIDADO!G139 -> 0 | G6: =F6/$F$2 -> #DIV/0! | H6: =CONSOLIDADO!I139 -> 0 | I6: =H6/$H$2 -> #DIV/0!
A7: DESPESA FINANCEIRA LÍQ. | B7: =CONSOLIDADO!C125 -> 0 | C7: =B7/$B$2 -> #DIV/0! | D7: =CONSOLIDADO!E125 -> 0 | E7: =D7/$D$2 -> #DIV/0! | F7: =CONSOLIDADO!G125 -> 0 | G7: =F7/$F$2 -> #DIV/0! | H7: =CONSOLIDADO!I125 -> 0 | I7: =H7/$H$2 -> #DIV/0!
A8: RESULTADO OPERACIONAL | B8: =CONSOLIDADO!C130 -> 0 | C8: =B8/$B$2 -> #DIV/0! | D8: =CONSOLIDADO!E130 -> 0 | E8: =D8/$D$2 -> #DIV/0! | F8: =CONSOLIDADO!G130 -> 0 | G8: =F8/$F$2 -> #DIV/0! | H8: =CONSOLIDADO!I130 -> 0 | I8: =H8/$H$2 -> #DIV/0!
A9: EBITDA | B9: =CONSOLIDADO!C157 -> 0 | C9: =B9/$B$2 -> #DIV/0! | D9: =CONSOLIDADO!E157 -> 0 | E9: =D9/$D$2 -> #DIV/0! | F9: =CONSOLIDADO!G157 -> 0 | G9: =F9/$F$2 -> #DIV/0! | H9: =CONSOLIDADO!I157 -> 0 | I9: =H9/$H$2 -> #DIV/0!
A10: GERAÇÃO DE CAIXA APÓS DF | B10: =CONSOLIDADO!C157-CONSOLIDADO!C125 -> 0 | C10: =B10/$B$2 -> #DIV/0! | D10: =CONSOLIDADO!E157-CONSOLIDADO!E125 -> 0 | E10: =D10/$D$2 -> #DIV/0! | F10: =CONSOLIDADO!G157-CONSOLIDADO!G125 -> 0 | G10: =F10/$F$2 -> #DIV/0! | H10: =CONSOLIDADO!I157-CONSOLIDADO!I125 -> 0 | I10: =H10/$H$2 -> #DIV/0!
B12: 44896 | C12: 45261 | D12: VAR. | E12: 45627 | F12: VAR. | G12: 45992 | H12: VAR.
A13: CONTAS A RECEBER | B13: =CONSOLIDADO!C14 -> 0 | C13: =CONSOLIDADO!E14 -> 0 | D13: =C13/B13-1 -> #DIV/0! | E13: =CONSOLIDADO!G14 -> 0 | F13: =E13/C13-1 -> #DIV/0! | G13: =CONSOLIDADO!I14 -> 0 | H13: =G13/E13-1 -> #DIV/0!
A14: ESTOQUE | B14: =CONSOLIDADO!C17 -> 0 | C14: =CONSOLIDADO!E17 -> 0 | D14: =C14/B14-1 -> #DIV/0! | E14: =CONSOLIDADO!G17 -> 0 | F14: =E14/C14-1 -> #DIV/0! | G14: =CONSOLIDADO!I17 -> 0 | H14: =G14/E14-1 -> #DIV/0!
A15: IMOBILIZADO | B15: =CONSOLIDADO!C43 -> 0 | C15: =CONSOLIDADO!E43 -> 0 | D15: =C15/B15-1 -> #DIV/0! | E15: =CONSOLIDADO!G43 -> 0 | F15: =E15/C15-1 -> #DIV/0! | G15: =CONSOLIDADO!I43 -> 0 | H15: =G15/E15-1 -> #DIV/0!
A16: FORNECEDORES | B16: =CONSOLIDADO!C52+CONSOLIDADO!C53 -> 0 | C16: =CONSOLIDADO!E52+CONSOLIDADO!E53 -> 0 | D16: =C16/B16-1 -> #DIV/0! | E16: =CONSOLIDADO!G52+CONSOLIDADO!G53 -> 0 | F16: =E16/C16-1 -> #DIV/0! | G16: =CONSOLIDADO!I52+CONSOLIDADO!I53 -> 0 | H16: =G16/E16-1 -> #DIV/0!
A17: DISPONIBILIDADE | B17: =CONSOLIDADO!C12+CONSOLIDADO!C13 -> 0 | C17: =CONSOLIDADO!E12+CONSOLIDADO!E13 -> 0 | D17: =C17/B17-1 -> #DIV/0! | E17: =CONSOLIDADO!G12+CONSOLIDADO!G13 -> 0 | F17: =E17/C17-1 -> #DIV/0! | G17: =CONSOLIDADO!I12+CONSOLIDADO!I13 -> 0 | H17: =G17/E17-1 -> #DIV/0!
A18: DÍVIDA TOTAL | B18: =CONSOLIDADO!C148 -> 0 | C18: =CONSOLIDADO!E148 -> 0 | D18: =C18/B18-1 -> #DIV/0! | E18: =CONSOLIDADO!G148 -> 0 | F18: =E18/C18-1 -> #DIV/0! | G18: =CONSOLIDADO!I148 -> 0 | H18: =G18/E18-1 -> #DIV/0!
A19: CURTO PRAZO | B19: =CONSOLIDADO!C146 -> 0 | C19: =CONSOLIDADO!E146 -> 0 | D19: =C19/B19-1 -> #DIV/0! | E19: =CONSOLIDADO!G146 -> 0 | F19: =E19/C19-1 -> #DIV/0! | G19: =CONSOLIDADO!I146 -> 0 | H19: =G19/E19-1 -> #DIV/0!
A20: LONGO PRAZO | B20: =CONSOLIDADO!C147 -> 0 | C20: =CONSOLIDADO!E147 -> 0 | D20: =C20/B20-1 -> #DIV/0! | E20: =CONSOLIDADO!G147 -> 0 | F20: =E20/C20-1 -> #DIV/0! | G20: =CONSOLIDADO!I147 -> 0 | H20: =G20/E20-1 -> #DIV/0!
A21: DÍVIDA LÍQUIDA | B21: =CONSOLIDADO!C145 -> 0 | C21: =CONSOLIDADO!E145 -> 0 | D21: =C21/B21-1 -> #DIV/0! | E21: =CONSOLIDADO!G145 -> 0 | F21: =E21/C21-1 -> #DIV/0! | G21: =CONSOLIDADO!I145 -> 0 | H21: =G21/E21-1 -> #DIV/0!
A22: ATIVO CIRCULANTE | B22: =CONSOLIDADO!C11 -> 0 | C22: =CONSOLIDADO!E11 -> 0 | D22: =C22/B22-1 -> #DIV/0! | E22: =CONSOLIDADO!G11 -> 0 | F22: =E22/C22-1 -> #DIV/0! | G22: =CONSOLIDADO!I11 -> 0 | H22: =G22/E22-1 -> #DIV/0!
A23: PATRIMONIO LÍQUIDO | B23: =CONSOLIDADO!C101 -> 0 | C23: =CONSOLIDADO!E101 -> 0 | D23: =C23/B23-1 -> #DIV/0! | E23: =CONSOLIDADO!G101 -> 0 | F23: =E23/C23-1 -> #DIV/0! | G23: =CONSOLIDADO!I101 -> 0 | H23: =G23/E23-1 -> #DIV/0!
A24: DÍVIDA LÍQUIDA/EBITDA | B24: =CONSOLIDADO!C160 -> N/A | C24: =CONSOLIDADO!E160 -> N/A | E24: =CONSOLIDADO!G160 -> N/A | G24: =CONSOLIDADO!I160 -> N/A
